Workbook

Sheet Summary of OEE
A1: MEP FAN LTD.
A2: MEP FAN LTD.
A3: Summary of OEE (2026)
A4: Month | B4: Detail | C4: Machine Capacity (Pcs) | D4: Production Qty. | F4: Availability (%) | G4: Performance (%) | H4: Quality (%) | I4: OEE (%) | J4: Remark's
D5: Total Production (pcs) | E5: Rejection (Pcs)
A6: January | B6: Total | C6: {=OEE!B13:D13} -> 1124393 | D6: 611910 | E6: 2815.9
B7: Total Acheivement (%) | C7: =OEE!B15 -> 0.54421363 | F7: {=OEE!E13:H13} -> 0.73746297 | G7: 0.7539491 | H7: 0.99461377 | I7: 0.60394047

Sheet OEE
A1: MEP FAN LTD.
A2: ="OEE Report ("&TEXT('Fan Lathe'!AM3,"mmmm yyyy")&")" -> OEE Report (January 2026)
A3: Section | B3: Machine Capacity (Pcs) | C3: Production Qty. | E3: Availability (%) | F3: Performance (%) | G3: Quality (%) | H3: OEE (%) | I3: Remark's
C4: Total Production (pcs) | D4: Rejection (Pcs)
A5: Fan Auto Die Casting | B5: {='Fan Auto Die Casting'!E68:G68} -> 185600 | C5: 85590 | D5: 700 | E5: {='Fan Auto Die Casting'!AI68:AL68} -> 0.46036877 | F5: 0.46115302 | G5: 0.99188782 | H5: 0.21057823
A6: Fan Power Press & Stamping | B6: {='Fan Power Press & Stamping'!E162:G162} -> 342100 | C6: 169367 | D6: 218 | E6: {='Fan Power Press & Stamping'!AL162:AO162} -> 0.56820815 | F6: 0.49508039 | G6: 0.99871451 | H6: 0.28094709
A7: Fan Auto Powder Coating | B7: {='Auto Powder Coating'!E130:G130} -> 306960 | C7: 162925 | D7: 521 | E7: {='Auto Powder Coating'!AI130:AL130} -> 0.51271478 | F7: 0.53076948 | G7: 0.9968124 | H7: 0.2712659
A8: Fan Lathe | B8: {='Fan Lathe'!E99:G99} -> 214850 | C8: 119580 | D8: 391 | E8: {='Fan Lathe'!AI99:AL99} -> 0.56683616 | F8: 0.55657435 | G8: 0.99674088 | H8: 0.31445826
A9: Fan Assemble | B9: {='Fan Assemble'!E37:G37} -> 35200 | C9: 35200 | D9: 985.9 | E9: {='Fan Assemble'!AI37:AL37} -> 0.95084746 | F9: 1 | G9: 0.97275458 | H9: 0.92494122
A10: Fan Armature | B10: {='Fan Armature'!E37:G37} -> 36297 | C10: 35862 | D10: 0 | E10: {='Fan Armature'!AI37:AL37} -> 0.95084746 | F10: 0.98801554 | G10: 1 | H10: 0.93945206
A11: Rechargeable Fan | B11: {='Fan Rechargeable'!E37:G37} -> 1500 | C11: 1500 | D11: 0 | E11: {='Fan Rechargeable'!AI37:AL37} -> 0.95238095 | F11: 1 | G11: 1 | H11: 0.95238095
A12: Exhaust Fan | B12: {='Exhaust Fan'!E37:G37} -> 1886 | C12: 1886 | D12: 0 | E12: {='Exhaust Fan'!AI37:AL37} -> 0.9375 | F12: 1 | G12: 1 | H12: 0.9375
A13: Total | B13: =SUM(B5:B12) -> 1124393 | C13: =SUM(C5:C12) -> 611910 | D13: =SUM(D5:D12) -> 2815.9 | E13: =IFERROR(AVERAGE(E5:E12),"0%") -> 0.73746297 | F13: =IFERROR(AVERAGE(F5:F12),"0%") -> 0.7539491 | G13: =IFERROR(AVERAGE(G5:G12),"0%") -> 0.99461377 | H13: =IFERROR(AVERAGE(H5:H12),"0%") -> 0.60394047
A15: Total Acheivement (%) | B15: =IFERROR((C13/B13),"") -> 0.54421363

Sheet Production Status
A1: MEP FAN LTD.
A2: ="MEP Fan Limited- Down Time & Running Time Status ("&TEXT('Fan Lathe'!AM3,"mmmm yyyy")&")" -> MEP Fan Limited- Down Time & Running Time Status (January 2026)
A3: Machine No. | B3: Planned Production Time (mins) | C3: Production Run Time (Mins) | D3: Machine Down Time (Mins) | E3: Production Running Time (%) | F3: Production Down Time (%) | G3: Remark's
A4: {='Down Time'!A5:A12} -> Fan Auto Die Casting | B4: ='Fan Auto Die Casting'!H68 -> 83520 | C4: {='Down Time'!AD5:AD12} -> -6620 | D4: {='Down Time'!AB5:AB12} -> 45070 | E4: =IF(B4=0, 0, C4/B4) -> -0.079262452 | F4: =IF(B4=0, 0, D4/B4) -> 0.53963123
A5: Fan Power Press & Stamping | B5: ='Fan Power Press & Stamping'!H162 -> 96660 | C5: 13846 | D5: 41077 | E5: =IF(B5=0, 0, C5/B5) -> 0.14324436 | F5: =IF(B5=0, 0, D5/B5) -> 0.42496379
A6: Fan Auto Powder Coating | B6: ='Auto Powder Coating'!H130 -> 34920 | C6: 888 | D6: 17016 | E6: =IF(B6=0, 0, C6/B6) -> 0.025429553 | F6: =IF(B6=0, 0, D6/B6) -> 0.48728522
A7: Fan Lathe | B7: ='Fan Lathe'!H99 -> 53100 | C7: 7098 | D7: 23001 | E7: =IF(B7=0, 0, C7/B7) -> 0.13367232 | F7: =IF(B7=0, 0, D7/B7) -> 0.43316384
A8: Fan Assemble | B8: ='Fan Assemble'!H37 -> 17700 | C8: 15960 | D8: 870 | E8: =IF(B8=0, 0, C8/B8) -> 0.90169492 | F8: =IF(B8=0, 0, D8/B8) -> 0.049152542
A9: Fan Armature | B9: ='Fan Armature'!H37 -> 17700 | C9: 15960 | D9: 870 | E9: =IF(B9=0, 0, C9/B9) -> 0.90169492 | F9: =IF(B9=0, 0, D9/B9) -> 0.049152542
A10: Rechargeable Fan | B10: ='Fan Rechargeable'!H37 -> 15120 | C10: 13680 | D10: 720 | E10: =IF(B10=0, 0, C10/B10) -> 0.9047619 | F10: =IF(B10=0, 0, D10/B10) -> 0.047619048
A11: Exhaust Fan | B11: ='Exhaust Fan'!H37 -> 2400 | C11: 2100 | D11: 150 | E11: =IF(B11=0, 0, C11/B11) -> 0.875 | F11: =IF(B11=0, 0, D11/B11) -> 0.0625
A12: SubTotal | B12: =SUM(B4:B11) -> 321120 | C12: =SUM(C4:C11) -> 62912 | D12: =SUM(D4:D11) -> 128774 | E12: =IF(B12=0, 0, C12/B12) -> 0.1959143 | F12: =IF(B12=0, 0, D12/B12) -> 0.4010152

Sheet Down Time
A1: MEP FAN LTD.
A2: ="Total Downtime Report ("&TEXT('Fan Lathe'!AM3,"mmmm yyyy")&")" -> Total Downtime Report (January 2026)
B3: 10 | C3: 11 | D3: 12 | E3: 13 | F3: 14 | G3: 15 | H3: 16 | I3: 17 | J3: 18 | K3: 19 | L3: 20 | M3: 21 | N3: 22 | O3: 23 | P3: 33 | Q3: 34 | R3: 35 | S3: 24 | T3: 25 | U3: 26 | V3: 27 | W3: 28 | X3: 29 | Y3: 30 | Z3: 31 | AA3: 32
A4: Machine No. | B4: Heater/Coil Problem | C4: Power Shutdown | D4: Machine Breakdown | E4: Die/ Mold Problem | F4: Model/ Die Change | G4: Air Presser Problem | H4: Water line Problem | I4: Lift Problem | J4: D Coil Insert | K4: RM Shortage | L4: Crean Problem | M4: Worker Absent | N4: Printer M/C Problem | O4: UPS shutdown | P4: Box Moving | Q4: Up Casting Meeting | R4: Sheet Cutting& Pipe Carry | S4: Load Problem | T4: Namaz | U4: Conveyor Belt Problem | V4: Fitting Problem | W4: Gas Presser Problem | X4: Mold polish & Clean | Y4: Alu. Ash Extraction | Z4: Robot Problems | AA4: Alu. Recipe Problem | AB4: Total Down Time (Mins) | AC4: Production Running Time ( Mins) | AD4: Total Run Time (Mins) | AE4: Total Down Time (%)
A5: Fan Auto Die Casting | B5: {=_xlfn.XLOOKUP(B3:AA3,'Fan Auto Die Casting'!K4:AG4,'Fan Auto Die Casting'!K68:AG68,0)} -> 810 | C5: 70 | D5: 42420 | E5: 370 | F5: 0 | G5: 60 | H5: 280 | I5: 0 | J5: 0 | K5: 0 | L5: 0 | M5: 0 | N5: 0 | O5: 0 | P5: 0 | Q5: 0 | R5: 0 | S5: 0 | T5: 90 | U5: 0 | V5: 0 | W5: 0 | X5: 640 | Y5: 90 | Z5: 0 | AA5: 240 | AB5: =SUM(B5:AA5) -> 45070 | AC5: {=TOP!B5:B12} -> 38450 | AD5: =AC5-AB5 -> -6620 | AE5: =IFERROR(AB5/AC5,0) -> 1.1721717
A6: Fan Power Press & Stamping | B6: {=_xlfn.XLOOKUP(B3:AA3,'Fan Power Press & Stamping'!K4:AJ4,'Fan Power Press & Stamping'!K162:AJ162,0)} -> 0 | C6: 0 | D6: 21211 | E6: 5775 | F6: 210 | G6: 25 | H6: 0 | I6: 0 | J6: 1355 | K6: 5284 | L6: 0 | M6: 0 | N6: 0 | O6: 140 | P6: 1005 | Q6: 40 | R6: 3075 | S6: 53 | T6: 2321 | U6: 0 | V6: 0 | W6: 0 | X6: 583 | Y6: 0 | Z6: 0 | AA6: 0 | AB6: =SUM(B6:AA6) -> 41077 | AC6: 54923 | AD6: =AC6-AB6 -> 13846 | AE6: =IFERROR(AB6/AC6,0) -> 0.74790161
A7: Fan Auto Powder Coating | B7: {=_xlfn.XLOOKUP(B3:AA3,'Auto Powder Coating'!K4:AG4,'Auto Powder Coating'!K130:AG130,0)} -> 100 | C7: 0 | D7: 16886 | E7: 0 | F7: 0 | G7: 0 | H7: 0 | I7: 0 | J7: 0 | K7: 0 | L7: 0 | M7: 0 | N7: 0 | O7: 0 | P7: 0 | Q7: 0 | R7: 0 | S7: 0 | T7: 30 | U7: 0 | V7: 0 | W7: 0 | X7: 0 | Y7: 0 | Z7: 0 | AA7: 0 | AB7: =SUM(B7:AA7) -> 17016 | AC7: 17904 | AD7: =AC7-AB7 -> 888 | AE7: =IFERROR(AB7/AC7,0) -> 0.95040214
A8: Fan Lathe | B8: {=_xlfn.XLOOKUP(B3:AA3,'Fan Lathe'!K4:AG4,'Fan Lathe'!K99:AG99,0)} -> 0 | C8: 0 | D8: 20461 | E8: 0 | F8: 0 | G8: 0 | H8: 0 | I8: 0 | J8: 0 | K8: 0 | L8: 0 | M8: 0 | N8: 0 | O8: 0 | P8: 0 | Q8: 0 | R8: 0 | S8: 0 | T8: 2540 | U8: 0 | V8: 0 | W8: 0 | X8: 0 | Y8: 0 | Z8: 0 | AA8: 0 | AB8: =SUM(B8:AA8) -> 23001 | AC8: 30099 | AD8: =AC8-AB8 -> 7098 | AE8: =IFERROR(AB8/AC8,0) -> 0.76417821
A9: Fan Assemble | B9: {=_xlfn.XLOOKUP(B3:AA3,'Fan Assemble'!K4:AG4,'Fan Assemble'!K37:AG37,0)} -> 0 | C9: 0 | D9: 0 | E9: 0 | F9: 0 | G9: 0 | H9: 0 | I9: 0 | J9: 0 | K9: 0 | L9: 0 | M9: 0 | N9: 0 | O9: 0 | P9: 0 | Q9: 0 | R9: 0 | S9: 0 | T9: 870 | U9: 0 | V9: 0 | W9: 0 | X9: 0 | Y9: 0 | Z9: 0 | AA9: 0 | AB9: =SUM(B9:AA9) -> 870 | AC9: 16830 | AD9: =AC9-AB9 -> 15960 | AE9: =IFERROR(AB9/AC9,0) -> 0.051693405
A10: Fan Armature | B10: {=_xlfn.XLOOKUP(B3:AA3,'Fan Armature'!K4:AG4,'Fan Armature'!K37:AG37,0)} -> 0 | C10: 0 | D10: 0 | E10: 0 | F10: 0 | G10: 0 | H10: 0 | I10: 0 | J10: 0 | K10: 0 | L10: 0 | M10: 0 | N10: 0 | O10: 0 | P10: 0 | Q10: 0 | R10: 0 | S10: 0 | T10: 870 | U10: 0 | V10: 0 | W10: 0 | X10: 0 | Y10: 0 | Z10: 0 | AA10: 0 | AB10: =SUM(B10:AA10) -> 870 | AC10: 16830 | AD10: =AC10-AB10 -> 15960 | AE10: =IFERROR(AB10/AC10,0) -> 0.051693405
A11: Rechargeable Fan | B11: {=_xlfn.XLOOKUP(B3:AA3,'Fan Rechargeable'!K4:AG4,'Fan Rechargeable'!K37:AG37,0)} -> 0 | C11: 0 | D11: 0 | E11: 0 | F11: 0 | G11: 0 | H11: 0 | I11: 0 | J11: 0 | K11: 0 | L11: 0 | M11: 0 | N11: 0 | O11: 0 | P11: 0 | Q11: 0 | R11: 0 | S11: 0 | T11: 720 | U11: 0 | V11: 0 | W11: 0 | X11: 0 | Y11: 0 | Z11: 0 | AA11: 0 | AB11: =SUM(B11:AA11) -> 720 | AC11: 14400 | AD11: =AC11-AB11 -> 13680 | AE11: =IFERROR(AB11/AC11,0) -> 0.05
A12: Exhaust Fan | B12: {=_xlfn.XLOOKUP(B3:AA3,'Exhaust Fan'!K4:AG4,'Exhaust Fan'!K37:AG37,0)} -> 0 | C12: 0 | D12: 0 | E12: 0 | F12: 0 | G12: 0 | H12: 0 | I12: 0 | J12: 0 | K12: 0 | L12: 0 | M12: 0 | N12: 0 | O12: 0 | P12: 0 | Q12: 0 | R12: 0 | S12: 0 | T12: 150 | U12: 0 | V12: 0 | W12: 0 | X12: 0 | Y12: 0 | Z12: 0 | AA12: 0 | AB12: =SUM(B12:AA12) -> 150 | AC12: 2250 | AD12: =AC12-AB12 -> 2100 | AE12: =IFERROR(AB12/AC12,0) -> 0.066666667
A13: Total (Mins) | B13: =SUM(B5:B12) -> 910 | C13: =SUM(C5:C12) -> 70 | D13: =SUM(D5:D12) -> 100978 | E13: =SUM(E5:E12) -> 6145 | F13: =SUM(F5:F12) -> 210 | G13: =SUM(G5:G12) -> 85 | H13: =SUM(H5:H12) -> 280 | I13: =SUM(I5:I12) -> 0 | ... O13: =SUM(O5:O12) -> 140 | S13: =SUM(S5:S12) -> 53 | T13: =SUM(T5:T12) -> 7591 | U13: =SUM(U5:U12) -> 0 | V13: =SUM(V5:V12) -> 0 | W13: =SUM(W5:W12) -> 0 | X13: =SUM(X5:X12) -> 1223 | Y13: =SUM(Y5:Y12) -> 90 | Z13: =SUM(Z5:Z12) -> 0 | ... AC13: =SUM(AC5:AC12) -> 191686 | AD13: =SUM(AD7:AD12) -> 55686 | AE13: =IFERROR(AB13/AC13,0) -> 0.67179658

Sheet TOP
A1: MEP FAN LTD.
A2: ="Production Output ("&TEXT('Fan Lathe'!AM3,"mmmm yyyy")&")" -> Production Output (January 2026)
A3: Section Name | B3: Production Running (hr) | C3: Machine Capacity (Pcs) | D3: Prodcution Qty. | F3: Standrad Wise Production Output (%) | G3: Remarks
D4: Production (pcs) | E4: Rejection (Pcs)
A5: Fan Auto Die Casting | B5: ='Fan Auto Die Casting'!J68 -> 38450 | C5: {='Fan Auto Die Casting'!E68:G68} -> 185600 | D5: 85590 | E5: 700 | F5: =IFERROR(D5/C5,"") -> 0.46115302
A6: Fan Power Press & Stamping | B6: ='Fan Power Press & Stamping'!J162 -> 54923 | C6: {='Fan Power Press & Stamping'!E162:G162} -> 342100 | D6: 169367 | E6: 218 | F6: =IFERROR(D6/C6,"") -> 0.49508039
A7: Fan Auto Powder Coating | B7: ='Auto Powder Coating'!J130 -> 17904 | C7: {='Auto Powder Coating'!E130:G130} -> 306960 | D7: 162925 | E7: 521 | F7: =IFERROR(D7/C7,"") -> 0.53076948
A8: Fan Lathe | B8: ='Fan Lathe'!J99 -> 30099 | C8: {='Fan Lathe'!E99:G99} -> 214850 | D8: 119580 | E8: 391 | F8: =IFERROR(D8/C8,"") -> 0.55657435
A9: Fan Assemble | B9: ='Fan Assemble'!J37 -> 16830 | C9: {='Fan Assemble'!E37:G37} -> 35200 | D9: 35200 | E9: 985.9 | F9: =IFERROR(D9/C9,"") -> 1
A10: Fan Armature | B10: ='Fan Armature'!J37 -> 16830 | C10: {='Fan Armature'!E37:G37} -> 36297 | D10: 35862 | E10: 0 | F10: =IFERROR(D10/C10,"") -> 0.98801554
A11: Rechargeable Fan | B11: ='Fan Rechargeable'!J37 -> 14400 | C11: {='Fan Rechargeable'!E37:G37} -> 1500 | D11: 1500 | E11: 0 | F11: =IFERROR(D11/C11,"") -> 1
A12: Exhaust Fan | B12: ='Exhaust Fan'!J37 -> 2250 | C12: {='Exhaust Fan'!E37:G37} -> 1886 | D12: 1886 | E12: 0 | F12: =IFERROR(D12/C12,"") -> 1
A13: Total | B13: =SUM(B5:B12) -> 191686 | C13: =SUM(C5:C12) -> 1124393 | D13: =SUM(D5:D12) -> 611910 | E13: =SUM(E5:E12) -> 2815.9 | F13: =IFERROR(D13/C13,"") -> 0.54421363

Sheet Fan Assemble
A1: MEP FAN LTD.
A2: Production Performance Analysis Report
A3: ="Fan Assemble Section ("&TEXT('Fan Lathe'!AM3,"mmmm yyyy")&")" -> Fan Assemble Section (January 2026) | AM3: ='Fan Lathe'!AM3 -> 46023
K4: 10 | L4: 11 | M4: 12 | N4: 13 | O4: 14 | P4: 15 | Q4: 16 | R4: 17 | S4: 18 | T4: 19 | U4: 20 | V4: 21 | W4: 22 | X4: 23 | Y4: 24 | Z4: 25 | AA4: 26 | AB4: 27 | AC4: 28 | AD4: 29 | AE4: 30 | AF4: 31 | AG4: 32
A5: Date | B5: Day | C5: Shift | D5: Machine Name | E5: Production Capacity (Pcs) | F5: Actual Prd. (Pcs) | G5: Rejection (Pcs) | H5: Planned Prd. Time (Min) | I5: Expected DownTime (Min) | J5: Total Prd. Run Time (Min) | K5: Heater/Coil Problem | L5: Power Shutdown | M5: Machine Breakdown | N5: Die/ Mold Problem | O5: Model/ Die Change | P5: Air Presser Problem | Q5: Water line Problem | R5: Lift Problem | S5: D Coil Insert | T5: RM Shortage | U5: Crean Problem | V5: Worker Absent | W5: Printer M/C Problem | X5: UPS shutdown | Y5: Load Problem | Z5: Namaz | AA5: Conveyor Belt Problem | AB5: Fitting Problem | AC5: Gas Presser Problem | AD5: Mold polish & Clean | AE5: Alu. Ash Extraction | AF5: Robot Problems | AG5: Alu. Recipe Problem | AH5: Total Down Time (Mins) | AI5: Availability (%) | AJ5: Performance (%) | AK5: Quality (%) | AL5: OEE (%) | AM5: Remarks
A6: =AM3 -> 46023 | B6: =A6 -> 46023 | C6: Morning | D6: Conveyor Belt | E6: 1225 | F6: 1225 | G6: 85 | H6: 660 | I6: =IF(E6<>"",30,0) -> 30 | J6: =H6-AH6 -> 630 | Z6: =IF(E6<>"",30,0) -> 30 | AH6: =SUM(K6:AG6) -> 30 | AI6: =IFERROR(J6/H6,"0") -> 0.95454545 | AJ6: =IFERROR(F6/E6,"0") -> 1 | AK6: =IFERROR(F6/(F6+G6),"0") -> 0.9351145 | AL6: =IFERROR(AK6*AJ6*AI6,"0") -> 0.8926093
A7: =A6+1 -> 46024 | B7: =A7 -> 46024 | C7: Morning | D7: Conveyor Belt | E7: 1000 | F7: 1000 | G7: 50 | H7: 480 | I7: =IF(E7<>"",30,0) -> 30 | J7: =H7-AH7 -> 450 | Z7: =IF(E7<>"",30,0) -> 30 | AH7: =SUM(K7:AG7) -> 30 | AI7: =IFERROR(J7/H7,"0") -> 0.9375 | AJ7: =IFERROR(F7/E7,"0") -> 1 | AK7: =IFERROR(F7/(F7+G7),"0") -> 0.95238095 | AL7: =IFERROR(AK7*AJ7*AI7,"0") -> 0.89285714
A8: =A7+1 -> 46025 | B8: =A8 -> 46025 | C8: Morning | D8: Conveyor Belt | E8: 1346 | F8: =1231+115 -> 1346 | G8: 55 | H8: 660 | I8: =IF(E8<>"",30,0) -> 30 | J8: =H8-AH8 -> 630 | Z8: =IF(E8<>"",30,0) -> 30 | AH8: =SUM(K8:AG8) -> 30 | AI8: =IFERROR(J8/H8,"0") -> 0.95454545 | AJ8: =IFERROR(F8/E8,"0") -> 1 | AK8: =IFERROR(F8/(F8+G8),"0") -> 0.96074233 | AL8: =IFERROR(AK8*AJ8*AI8,"0") -> 0.91707222
A9: =A8+1 -> 46026 | B9: =A9 -> 46026 | C9: Morning | D9: Conveyor Belt | E9: 1346 | F9: =1231+115 -> 1346 | G9: 44 | H9: 660 | I9: =IF(E9<>"",30,0) -> 30 | J9: =H9-AH9 -> 630 | Z9: =IF(E9<>"",30,0) -> 30 | AH9: =SUM(K9:AG9) -> 30 | AI9: =IFERROR(J9/H9,"0") -> 0.95454545 | AJ9: =IFERROR(F9/E9,"0") -> 1 | AK9: =IFERROR(F9/(F9+G9),"0") -> 0.96834532 | AL9: =IFERROR(AK9*AJ9*AI9,"0") -> 0.92432963
A10: =A9+1 -> 46027 | B10: =A10 -> 46027 | C10: Morning | D10: Conveyor Belt | E10: 1346 | F10: =1231+115 -> 1346 | G10: 58 | H10: 660 | I10: =IF(E10<>"",30,0) -> 30 | J10: =H10-AH10 -> 630 | Z10: =IF(E10<>"",30,0) -> 30 | AH10: =SUM(K10:AG10) -> 30 | AI10: =IFERROR(J10/H10,"0") -> 0.95454545 | AJ10: =IFERROR(F10/E10,"0") -> 1 | AK10: =IFERROR(F10/(F10+G10),"0") -> 0.95868946 | AL10: =IFERROR(AK10*AJ10*AI10,"0") -> 0.91511267
A11: =A10+1 -> 46028 | B11: =A11 -> 46028 | C11: Morning | D11: Conveyor Belt | E11: 1346 | F11: =1231+115 -> 1346 | G11: 54.9 | H11: 660 | I11: =IF(E11<>"",30,0) -> 30 | J11: =H11-AH11 -> 630 | Z11: =IF(E11<>"",30,0) -> 30 | AH11: =SUM(K11:AG11) -> 30 | AI11: =IFERROR(J11/H11,"0") -> 0.95454545 | AJ11: =IFERROR(F11/E11,"0") -> 1 | AK11: =IFERROR(F11/(F11+G11),"0") -> 0.96081091 | AL11: =IFERROR(AK11*AJ11*AI11,"0") -> 0.91713768
A12: =A11+1 -> 46029 | B12: =A12 -> 46029 | C12: Morning | D12: Conveyor Belt | E12: 1346 | F12: =1231+115 -> 1346 | G12: 51.8 | H12: 660 | I12: =IF(E12<>"",30,0) -> 30 | J12: =H12-AH12 -> 630 | Z12: =IF(E12<>"",30,0) -> 30 | AH12: =SUM(K12:AG12) -> 30 | AI12: =IFERROR(J12/H12,"0") -> 0.95454545 | AJ12: =IFERROR(F12/E12,"0") -> 1 | AK12: =IFERROR(F12/(F12+G12),"0") -> 0.96294177 | AL12: =IFERROR(AK12*AJ12*AI12,"0") -> 0.91917169
A13: =A12+1 -> 46030 | B13: =A13 -> 46030 | C13: Morning | D13: Conveyor Belt | E13: 1346 | F13: =1231+115 -> 1346 | G13: 48.7 | H13: 660 | I13: =IF(E13<>"",30,0) -> 30 | J13: =H13-AH13 -> 630 | Z13: =IF(E13<>"",30,0) -> 30 | AH13: =SUM(K13:AG13) -> 30 | AI13: =IFERROR(J13/H13,"0") -> 0.95454545 | AJ13: =IFERROR(F13/E13,"0") -> 1 | AK13: =IFERROR(F13/(F13+G13),"0") -> 0.9650821 | AL13: =IFERROR(AK13*AJ13*AI13,"0") -> 0.92121473
A14: =A13+1 -> 46031 | B14: =A14 -> 46031 | C14: Morning | D14: Conveyor Belt | I14: =IF(E14<>"",30,0) -> 0 | J14: =H14-AH14 -> 0 | Z14: =IF(E14<>"",30,0) -> 0 | AH14: =SUM(K14:AG14) -> 0 | AI14: =IFERROR(J14/H14,"0") -> 0 | AJ14: =IFERROR(F14/E14,"0") -> 0 | AK14: =IFERROR(F14/(F14+G14),"0") -> 0 | AL14: =IFERROR(AK14*AJ14*AI14,"0") -> 0
A15: =A14+1 -> 46032 | B15: =A15 -> 46032 | C15: Morning | D15: Conveyor Belt | E15: 1346 | F15: =1231+115 -> 1346 | G15: 42.5 | H15: 660 | I15: =IF(E15<>"",30,0) -> 30 | J15: =H15-AH15 -> 630 | Z15: =IF(E15<>"",30,0) -> 30 | AH15: =SUM(K15:AG15) -> 30 | AI15: =IFERROR(J15/H15,"0") -> 0.95454545 | AJ15: =IFERROR(F15/E15,"0") -> 1 | AK15: =IFERROR(F15/(F15+G15),"0") -> 0.96939143 | AL15: =IFERROR(AK15*AJ15*AI15,"0") -> 0.92532818
A16: =A15+1 -> 46033 | B16: =A16 -> 46033 | C16: Morning | D16: Conveyor Belt | E16: 1346 | F16: =1231+115 -> 1346 | G16: 39.4 | H16: 660 | I16: =IF(E16<>"",30,0) -> 30 | J16: =H16-AH16 -> 630 | Z16: =IF(E16<>"",30,0) -> 30 | AH16: =SUM(K16:AG16) -> 30 | AI16: =IFERROR(J16/H16,"0") -> 0.95454545 | AJ16: =IFERROR(F16/E16,"0") -> 1 | AK16: =IFERROR(F16/(F16+G16),"0") -> 0.97156056 | AL16: =IFERROR(AK16*AJ16*AI16,"0") -> 0.92739872
A17: =A16+1 -> 46034 | B17: =A17 -> 46034 | C17: Morning | D17: Conveyor Belt | E17: 1346 | F17: =1231+115 -> 1346 | G17: 36.3 | H17: 660 | I17: =IF(E17<>"",30,0) -> 30 | J17: =H17-AH17 -> 630 | Z17: =IF(E17<>"",30,0) -> 30 | AH17: =SUM(K17:AG17) -> 30 | AI17: =IFERROR(J17/H17,"0") -> 0.95454545 | AJ17: =IFERROR(F17/E17,"0") -> 1 | AK17: =IFERROR(F17/(F17+G17),"0") -> 0.97373942 | AL17: =IFERROR(AK17*AJ17*AI17,"0") -> 0.92947854
A18: =A17+1 -> 46035 | B18: =A18 -> 46035 | C18: Morning | D18: Conveyor Belt | E18: 1346 | F18: =1231+115 -> 1346 | G18: 33.2 | H18: 660 | I18: =IF(E18<>"",30,0) -> 30 | J18: =H18-AH18 -> 630 | Z18: =IF(E18<>"",30,0) -> 30 | AH18: =SUM(K18:AG18) -> 30 | AI18: =IFERROR(J18/H18,"0") -> 0.95454545 | AJ18: =IFERROR(F18/E18,"0") -> 1 | AK18: =IFERROR(F18/(F18+G18),"0") -> 0.97592807 | AL18: =IFERROR(AK18*AJ18*AI18,"0") -> 0.93156771
A19: =A18+1 -> 46036 | B19: =A19 -> 46036 | C19: Morning | D19: Conveyor Belt | E19: 1346 | F19: =1231+115 -> 1346 | G19: 30.1 | H19: 660 | I19: =IF(E19<>"",30,0) -> 30 | J19: =H19-AH19 -> 630 | Z19: =IF(E19<>"",30,0) -> 30 | AH19: =SUM(K19:AG19) -> 30 | AI19: =IFERROR(J19/H19,"0") -> 0.95454545 | AJ19: =IFERROR(F19/E19,"0") -> 1 | AK19: =IFERROR(F19/(F19+G19),"0") -> 0.97812659 | AL19: =IFERROR(AK19*AJ19*AI19,"0") -> 0.93366629
A20: =A19+1 -> 46037 | B20: =A20 -> 46037 | C20: Morning | D20: Conveyor Belt | E20: 1321 | F20: =1231+115-25 -> 1321 | G20: 85 | H20: 660 | I20: =IF(E20<>"",30,0) -> 30 | J20: =H20-AH20 -> 630 | Z20: =IF(E20<>"",30,0) -> 30 | AH20: =SUM(K20:AG20) -> 30 | AI20: =IFERROR(J20/H20,"0") -> 0.95454545 | AJ20: =IFERROR(F20/E20,"0") -> 1 | AK20: =IFERROR(F20/(F20+G20),"0") -> 0.93954481 | AL20: =IFERROR(AK20*AJ20*AI20,"0") -> 0.89683823
A21: =A20+1 -> 46038 | B21: =A21 -> 46038 | C21: Morning | D21: Conveyor Belt | E21: 1000 | F21: 1000 | H21: 480 | J21: =H21-AH21 -> 450 | Z21: =IF(E21<>"",30,0) -> 30 | AH21: =SUM(K21:AG21) -> 30 | AI21: =IFERROR(J21/H21,"0") -> 0.9375 | AJ21: =IFERROR(F21/E21,"0") -> 1 | AK21: =IFERROR(F21/(F21+G21),"0") -> 1 | AL21: =IFERROR(AK21*AJ21*AI21,"0") -> 0.9375
A22: =A21+1 -> 46039 | B22: =A22 -> 46039 | C22: Morning | D22: Conveyor Belt | E22: 1231 | F22: 1231 | G22: 45 | H22: 660 | I22: =IF(E22<>"",30,0) -> 30 | J22: =H22-AH22 -> 630 | Z22: =IF(E22<>"",30,0) -> 30 | AH22: =SUM(K22:AG22) -> 30 | AI22: =IFERROR(J22/H22,"0") -> 0.95454545 | AJ22: =IFERROR(F22/E22,"0") -> 1 | AK22: =IFERROR(F22/(F22+G22),"0") -> 0.96473354 | AL22: =IFERROR(AK22*AJ22*AI22,"0") -> 0.92088202
A23: =A22+1 -> 46040 | B23: =A23 -> 46040 | C23: Morning | D23: Conveyor Belt | E23: 1231 | F23: 1231 | G23: 20 | H23: 660 | I23: =IF(E23<>"",30,0) -> 30 | J23: =H23-AH23 -> 630 | Z23: =IF(E23<>"",30,0) -> 30 | AH23: =SUM(K23:AG23) -> 30 | AI23: =IFERROR(J23/H23,"0") -> 0.95454545 | AJ23: =IFERROR(F23/E23,"0") -> 1 | AK23: =IFERROR(F23/(F23+G23),"0") -> 0.98401279 | AL23: =IFERROR(AK23*AJ23*AI23,"0") -> 0.93928494
A24: =A23+1 -> 46041 | B24: =A24 -> 46041 | C24: Morning | D24: Conveyor Belt | E24: 1231 | F24: 1231 | G24: 15 | H24: 660 | I24: =IF(E24<>"",30,0) -> 30 | J24: =H24-AH24 -> 630 | Z24: =IF(E24<>"",30,0) -> 30 | AH24: =SUM(K24:AG24) -> 30 | AI24: =IFERROR(J24/H24,"0") -> 0.95454545 | AJ24: =IFERROR(F24/E24,"0") -> 1 | AK24: =IFERROR(F24/(F24+G24),"0") -> 0.98796148 | AL24: =IFERROR(AK24*AJ24*AI24,"0") -> 0.94305414
A25: =A24+1 -> 46042 | B25: =A25 -> 46042 | C25: Morning | D25: Conveyor Belt | E25: 1231 | F25: 1231 | G25: 33 | H25: 660 | I25: =IF(E25<>"",30,0) -> 30 | J25: =H25-AH25 -> 630 | Z25: =IF(E25<>"",30,0) -> 30 | AH25: =SUM(K25:AG25) -> 30 | AI25: =IFERROR(J25/H25,"0") -> 0.95454545 | AJ25: =IFERROR(F25/E25,"0") -> 1 | AK25: =IFERROR(F25/(F25+G25),"0") -> 0.97389241 | AL25: =IFERROR(AK25*AJ25*AI25,"0") -> 0.92962457
A26: =A25+1 -> 46043 | B26: =A26 -> 46043 | C26: Morning | D26: Conveyor Belt | E26: 1231 | F26: 1231 | G26: 57 | H26: 660 | I26: =IF(E26<>"",30,0) -> 30 | J26: =H26-AH26 -> 630 | Z26: =IF(E26<>"",30,0) -> 30 | AH26: =SUM(K26:AG26) -> 30 | AI26: =IFERROR(J26/H26,"0") -> 0.95454545 | AJ26: =IFERROR(F26/E26,"0") -> 1 | AK26: =IFERROR(F26/(F26+G26),"0") -> 0.95574534 | AL26: =IFERROR(AK26*AJ26*AI26,"0") -> 0.91230237
A27: =A26+1 -> 46044 | B27: =A27 -> 46044 | C27: Morning | D27: Conveyor Belt | E27: 1231 | F27: 1231 | G27: 10 | H27: 660 | I27: =IF(E27<>"",30,0) -> 30 | J27: =H27-AH27 -> 630 | Z27: =IF(E27<>"",30,0) -> 30 | AH27: =SUM(K27:AG27) -> 30 | AI27: =IFERROR(J27/H27,"0") -> 0.95454545 | AJ27: =IFERROR(F27/E27,"0") -> 1 | AK27: =IFERROR(F27/(F27+G27),"0") -> 0.99194198 | AL27: =IFERROR(AK27*AJ27*AI27,"0") -> 0.94685371
A28: =A27+1 -> 46045 | B28: =A28 -> 46045 | C28: Morning | D28: Conveyor Belt | I28: =IF(E28<>"",30,0) -> 0 | J28: =H28-AH28 -> 0 | Z28: =IF(E28<>"",30,0) -> 0 | AH28: =SUM(K28:AG28) -> 0 | AI28: =IFERROR(J28/H28,"0") -> 0 | AJ28: =IFERROR(F28/E28,"0") -> 0 | AK28: =IFERROR(F28/(F28+G28),"0") -> 0 | AL28: =IFERROR(AK28*AJ28*AI28,"0") -> 0
A29: =A28+1 -> 46046 | B29: =A29 -> 46046 | C29: Morning | D29: Conveyor Belt | E29: 1231 | F29: 1231 | G29: 15 | H29: 660 | I29: =IF(E29<>"",30,0) -> 30 | J29: =H29-AH29 -> 630 | Z29: =IF(E29<>"",30,0) -> 30 | AH29: =SUM(K29:AG29) -> 30 | AI29: =IFERROR(J29/H29,"0") -> 0.95454545 | AJ29: =IFERROR(F29/E29,"0") -> 1 | AK29: =IFERROR(F29/(F29+G29),"0") -> 0.98796148 | AL29: =IFERROR(AK29*AJ29*AI29,"0") -> 0.94305414
A30: =A29+1 -> 46047 | B30: =A30 -> 46047 | C30: Morning | D30: Conveyor Belt | E30: 1231 | F30: 1231 | G30: 13 | H30: 660 | I30: =IF(E30<>"",30,0) -> 30 | J30: =H30-AH30 -> 630 | Z30: =IF(E30<>"",30,0) -> 30 | AH30: =SUM(K30:AG30) -> 30 | AI30: =IFERROR(J30/H30,"0") -> 0.95454545 | AJ30: =IFERROR(F30/E30,"0") -> 1 | AK30: =IFERROR(F30/(F30+G30),"0") -> 0.98954984 | AL30: =IFERROR(AK30*AJ30*AI30,"0") -> 0.9445703
A31: =A30+1 -> 46048 | B31: =A31 -> 46048 | C31: Morning | D31: Conveyor Belt | E31: 1000 | F31: 1000 | G31: 12 | H31: 480 | I31: =IF(E31<>"",30,0) -> 30 | J31: =H31-AH31 -> 450 | Z31: =IF(E31<>"",30,0) -> 30 | AH31: =SUM(K31:AG31) -> 30 | AI31: =IFERROR(J31/H31,"0") -> 0.9375 | AJ31: =IFERROR(F31/E31,"0") -> 1 | AK31: =IFERROR(F31/(F31+G31),"0") -> 0.98814229 | AL31: =IFERROR(AK31*AJ31*AI31,"0") -> 0.9263834
A32: =A31+1 -> 46049 | B32: =A32 -> 46049 | C32: Morning | D32: Conveyor Belt | E32: 1000 | F32: 1000 | G32: 8 | H32: 480 | I32: =IF(E32<>"",30,0) -> 30 | J32: =H32-AH32 -> 450 | Z32: =IF(E32<>"",30,0) -> 30 | AH32: =SUM(K32:AG32) -> 30 | AI32: =IFERROR(J32/H32,"0") -> 0.9375 | AJ32: =IFERROR(F32/E32,"0") -> 1 | AK32: =IFERROR(F32/(F32+G32),"0") -> 0.99206349 | AL32: =IFERROR(AK32*AJ32*AI32,"0") -> 0.93005952
A33: =A32+1 -> 46050 | B33: =A33 -> 46050 | C33: Morning | D33: Conveyor Belt | E33: 1000 | F33: 1000 | G33: 21 | H33: 480 | I33: =IF(E33<>"",30,0) -> 30 | J33: =H33-AH33 -> 450 | Z33: =IF(E33<>"",30,0) -> 30 | AH33: =SUM(K33:AG33) -> 30 | AI33: =IFERROR(J33/H33,"0") -> 0.9375 | AJ33: =IFERROR(F33/E33,"0") -> 1 | AK33: =IFERROR(F33/(F33+G33),"0") -> 0.97943193 | AL33: =IFERROR(AK33*AJ33*AI33,"0") -> 0.91821743
A34: =A33+1 -> 46051 | B34: =A34 -> 46051 | C34: Morning | D34: Conveyor Belt | E34: 1000 | F34: 1000 | G34: 11 | H34: 480 | I34: =IF(E34<>"",30,0) -> 30 | J34: =H34-AH34 -> 450 | Z34: =IF(E34<>"",30,0) -> 30 | AH34: =SUM(K34:AG34) -> 30 | AI34: =IFERROR(J34/H34,"0") -> 0.9375 | AJ34: =IFERROR(F34/E34,"0") -> 1 | AK34: =IFERROR(F34/(F34+G34),"0") -> 0.98911968 | AL34: =IFERROR(AK34*AJ34*AI34,"0") -> 0.9272997
A35: =A34+1 -> 46052 | B35: =A35 -> 46052 | C35: Morning | D35: Conveyor Belt | E35: 1000 | F35: 1000 | G35: 5 | H35: 480 | I35: =IF(E35<>"",30,0) -> 30 | J35: =H35-AH35 -> 450 | Z35: =IF(E35<>"",30,0) -> 30 | AH35: =SUM(K35:AG35) -> 30 | AI35: =IFERROR(J35/H35,"0") -> 0.9375 | AJ35: =IFERROR(F35/E35,"0") -> 1 | AK35: =IFERROR(F35/(F35+G35),"0") -> 0.99502488 | AL35: =IFERROR(AK35*AJ35*AI35,"0") -> 0.93283582
A36: =A35+1 -> 46053 | B36: =A36 -> 46053 | C36: Morning | D36: Conveyor Belt | E36: 1000 | F36: 1000 | G36: 7 | H36: 480 | I36: =IF(E36<>"",30,0) -> 30 | J36: =H36-AH36 -> 450 | Z36: =IF(E36<>"",30,0) -> 30 | AH36: =SUM(K36:AG36) -> 30 | AI36: =IFERROR(J36/H36,"0") -> 0.9375 | AJ36: =IFERROR(F36/E36,"0") -> 1 | AK36: =IFERROR(F36/(F36+G36),"0") -> 0.99304866 | AL36: =IFERROR(AK36*AJ36*AI36,"0") -> 0.93098312
A37: Total: | E37: =SUM(E6:E36) -> 35200 | F37: =SUM(F6:F36) -> 35200 | G37: =SUM(G6:G36) -> 985.9 | H37: =SUM(H6:H36) -> 17700 | I37: =SUM(I6:I36) -> 840 | J37: =SUM(J6:J36) -> 16830 | K37: =SUM(K6:K36) -> 0 | L37: =SUM(L6:L36) -> 0 | ... AH37: =SUM(AH6:AH36) -> 870 | AI37: =IFERROR(J37/H37,0) -> 0.95084746 | AJ37: =IFERROR(F37/E37,0) -> 1 | AK37: =IFERROR(F37/(F37+G37),0) -> 0.97275458 | AL37: =IFERROR(AK37*AJ37*AI37,0) -> 0.92494122

Sheet Fan Armature
A1: MEP FAN LTD.
A2: Production Performance Analysis Report
A3: ="Fan Armature Section ("&TEXT('Fan Lathe'!AM3,"mmmm yyyy")&")" -> Fan Armature Section (January 2026) | AM3: ='Fan Lathe'!AM3 -> 46023
K4: 10 | L4: 11 | M4: 12 | N4: 13 | O4: 14 | P4: 15 | Q4: 16 | R4: 17 | S4: 18 | T4: 19 | U4: 20 | V4: 21 | W4: 22 | X4: 23 | Y4: 24 | Z4: 25 | AA4: 26 | AB4: 27 | AC4: 28 | AD4: 29 | AE4: 30 | AF4: 31 | AG4: 32
A5: Date | B5: Day | C5: Shift | D5: Machine Name | E5: Machine Capacity (Pcs) | F5: Actual Prd. (Pcs) | G5: Rejection (Pcs) | H5: Planned Prd. Time (Min) | I5: Expected DownTime (Min) | J5: Total Prd. Run Time (Min) | K5: Heater/Coil Problem | L5: Power Shutdown | M5: Machine Breakdown | N5: Die/ Mold Problem | O5: Model/ Die Change | P5: Air Presser Problem | Q5: Water line Problem | R5: Lift Problem | S5: D Coil Insert | T5: RM Shortage | U5: Crean Problem | V5: Worker Absent | W5: Printer M/C Problem | X5: UPS shutdown | Y5: Load Problem | Z5: Namaz | AA5: Conveyor Belt Problem | AB5: Fitting Problem | AC5: Gas Presser Problem | AD5: Mold polish & Clean | AE5: Alu. Ash Extraction | AF5: Robot Problems | AG5: Alu. Recipe Problem | AH5: Total Down Time (Mins) | AI5: Availability (%) | AJ5: Performance (%) | AK5: Quality (%) | AL5: OEE (%) | AM5: Remarks
A6: =AM3 -> 46023 | B6: =A6 -> 46023 | C6: Morning | D6: Winding Machine | E6: 1345 | F6: 1330 | G6: 0 | H6: 660 | I6: =IF(E6<>"",30,0) -> 30 | J6: =H6-AH6 -> 630 | Z6: =IF(E6<>"",30,0) -> 30 | AH6: =SUM(K6:AG6) -> 30 | AI6: =IFERROR(J6/H6,"0") -> 0.95454545 | AJ6: =IFERROR(F6/E6,"0") -> 0.98884758 | AK6: =IFERROR(F6/(F6+G6),"0") -> 1 | AL6: =IFERROR(AK6*AJ6*AI6,"0") -> 0.94389997
A7: =A6+1 -> 46024 | B7: =A7 -> 46024 | C7: Morning | D7: Winding Machine | E7: 1025 | F7: 1010 | G7: 0 | H7: 480 | I7: =IF(E7<>"",30,0) -> 30 | J7: =H7-AH7 -> 450 | Z7: =IF(E7<>"",30,0) -> 30 | AH7: =SUM(K7:AG7) -> 30 | AI7: =IFERROR(J7/H7,"0") -> 0.9375 | AJ7: =IFERROR(F7/E7,"0") -> 0.98536585 | AK7: =IFERROR(F7/(F7+G7),"0") -> 1 | AL7: =IFERROR(AK7*AJ7*AI7,"0") -> 0.92378049
A8: =A7+1 -> 46025 | B8: =A8 -> 46025 | C8: Morning | D8: Winding Machine | E8: 1400 | F8: 1385 | G8: 0 | H8: 660 | I8: =IF(E8<>"",30,0) -> 30 | J8: =H8-AH8 -> 630 | Z8: =IF(E8<>"",30,0) -> 30 | AH8: =SUM(K8:AG8) -> 30 | AI8: =IFERROR(J8/H8,"0") -> 0.95454545 | AJ8: =IFERROR(F8/E8,"0") -> 0.98928571 | AK8: =IFERROR(F8/(F8+G8),"0") -> 1 | AL8: =IFERROR(AK8*AJ8*AI8,"0") -> 0.94431818
A9: =A8+1 -> 46026 | B9: =A9 -> 46026 | C9: Morning | D9: Winding Machine | E9: 1400 | F9: 1385 | G9: 0 | H9: 660 | I9: =IF(E9<>"",30,0) -> 30 | J9: =H9-AH9 -> 630 | Z9: =IF(E9<>"",30,0) -> 30 | AH9: =SUM(K9:AG9) -> 30 | AI9: =IFERROR(J9/H9,"0") -> 0.95454545 | AJ9: =IFERROR(F9/E9,"0") -> 0.98928571 | AK9: =IFERROR(F9/(F9+G9),"0") -> 1 | AL9: =IFERROR(AK9*AJ9*AI9,"0") -> 0.94431818
A10: =A9+1 -> 46027 | B10: =A10 -> 46027 | C10: Morning | D10: Winding Machine | E10: 1405 | F10: 1390 | G10: 0 | H10: 660 | I10: =IF(E10<>"",30,0) -> 30 | J10: =H10-AH10 -> 630 | Z10: =IF(E10<>"",30,0) -> 30 | AH10: =SUM(K10:AG10) -> 30 | AI10: =IFERROR(J10/H10,"0") -> 0.95454545 | AJ10: =IFERROR(F10/E10,"0") -> 0.98932384 | AK10: =IFERROR(F10/(F10+G10),"0") -> 1 | AL10: =IFERROR(AK10*AJ10*AI10,"0") -> 0.94435458
A11: =A10+1 -> 46028 | B11: =A11 -> 46028 | C11: Morning | D11: Winding Machine | E11: 1415 | F11: 1400 | G11: 0 | H11: 660 | I11: =IF(E11<>"",30,0) -> 30 | J11: =H11-AH11 -> 630 | Z11: =IF(E11<>"",30,0) -> 30 | AH11: =SUM(K11:AG11) -> 30 | AI11: =IFERROR(J11/H11,"0") -> 0.95454545 | AJ11: =IFERROR(F11/E11,"0") -> 0.98939929 | AK11: =IFERROR(F11/(F11+G11),"0") -> 1 | AL11: =IFERROR(AK11*AJ11*AI11,"0") -> 0.9444266
A12: =A11+1 -> 46029 | B12: =A12 -> 46029 | C12: Morning | D12: Winding Machine | E12: 1415 | F12: 1400 | G12: 0 | H12: 660 | I12: =IF(E12<>"",30,0) -> 30 | J12: =H12-AH12 -> 630 | Z12: =IF(E12<>"",30,0) -> 30 | AH12: =SUM(K12:AG12) -> 30 | AI12: =IFERROR(J12/H12,"0") -> 0.95454545 | AJ12: =IFERROR(F12/E12,"0") -> 0.98939929 | AK12: =IFERROR(F12/(F12+G12),"0") -> 1 | AL12: =IFERROR(AK12*AJ12*AI12,"0") -> 0.9444266
A13: =A12+1 -> 46030 | B13: =A13 -> 46030 | C13: Morning | D13: Winding Machine | E13: 1415 | F13: 1400 | G13: 0 | H13: 660 | I13: =IF(E13<>"",30,0) -> 30 | J13: =H13-AH13 -> 630 | Z13: =IF(E13<>"",30,0) -> 30 | AH13: =SUM(K13:AG13) -> 30 | AI13: =IFERROR(J13/H13,"0") -> 0.95454545 | AJ13: =IFERROR(F13/E13,"0") -> 0.98939929 | AK13: =IFERROR(F13/(F13+G13),"0") -> 1 | AL13: =IFERROR(AK13*AJ13*AI13,"0") -> 0.9444266
A14: =A13+1 -> 46031 | B14: =A14 -> 46031 | C14: Morning | D14: Winding Machine | F14: 0 | G14: 0 | I14: =IF(E14<>"",30,0) -> 0 | J14: =H14-AH14 -> 0 | Z14: =IF(E14<>"",30,0) -> 0 | AH14: =SUM(K14:AG14) -> 0 | AI14: =IFERROR(J14/H14,"0") -> 0 | AJ14: =IFERROR(F14/E14,"0") -> 0 | AK14: =IFERROR(F14/(F14+G14),"0") -> 0 | AL14: =IFERROR(AK14*AJ14*AI14,"0") -> 0
A15: =A14+1 -> 46032 | B15: =A15 -> 46032 | C15: Morning | D15: Winding Machine | E15: 1427 | F15: 1412 | G15: 0 | H15: 660 | I15: =IF(E15<>"",30,0) -> 30 | J15: =H15-AH15 -> 630 | Z15: =IF(E15<>"",30,0) -> 30 | AH15: =SUM(K15:AG15) -> 30 | AI15: =IFERROR(J15/H15,"0") -> 0.95454545 | AJ15: =IFERROR(F15/E15,"0") -> 0.98948844 | AK15: =IFERROR(F15/(F15+G15),"0") -> 1 | AL15: =IFERROR(AK15*AJ15*AI15,"0") -> 0.94451169
A16: =A15+1 -> 46033 | B16: =A16 -> 46033 | C16: Morning | D16: Winding Machine | E16: 1030 | F16: 1015 | G16: 0 | H16: 660 | I16: =IF(E16<>"",30,0) -> 30 | J16: =H16-AH16 -> 630 | Z16: =IF(E16<>"",30,0) -> 30 | AH16: =SUM(K16:AG16) -> 30 | AI16: =IFERROR(J16/H16,"0") -> 0.95454545 | AJ16: =IFERROR(F16/E16,"0") -> 0.98543689 | AK16: =IFERROR(F16/(F16+G16),"0") -> 1 | AL16: =IFERROR(AK16*AJ16*AI16,"0") -> 0.94064431
A17: =A16+1 -> 46034 | B17: =A17 -> 46034 | C17: Morning | D17: Winding Machine | E17: 1400 | F17: 1385 | G17: 0 | H17: 660 | I17: =IF(E17<>"",30,0) -> 30 | J17: =H17-AH17 -> 630 | Z17: =IF(E17<>"",30,0) -> 30 | AH17: =SUM(K17:AG17) -> 30 | AI17: =IFERROR(J17/H17,"0") -> 0.95454545 | AJ17: =IFERROR(F17/E17,"0") -> 0.98928571 | AK17: =IFERROR(F17/(F17+G17),"0") -> 1 | AL17: =IFERROR(AK17*AJ17*AI17,"0") -> 0.94431818
A18: =A17+1 -> 46035 | B18: =A18 -> 46035 | C18: Morning | D18: Winding Machine | E18: 1405 | F18: 1390 | G18: 0 | H18: 660 | I18: =IF(E18<>"",30,0) -> 30 | J18: =H18-AH18 -> 630 | Z18: =IF(E18<>"",30,0) -> 30 | AH18: =SUM(K18:AG18) -> 30 | AI18: =IFERROR(J18/H18,"0") -> 0.95454545 | AJ18: =IFERROR(F18/E18,"0") -> 0.98932384 | AK18: =IFERROR(F18/(F18+G18),"0") -> 1 | AL18: =IFERROR(AK18*AJ18*AI18,"0") -> 0.94435458
A19: =A18+1 -> 46036 | B19: =A19 -> 46036 | C19: Morning | D19: Winding Machine | E19: 1035 | F19: 1020 | G19: 0 | H19: 660 | I19: =IF(E19<>"",30,0) -> 30 | J19: =H19-AH19 -> 630 | Z19: =IF(E19<>"",30,0) -> 30 | AH19: =SUM(K19:AG19) -> 30 | AI19: =IFERROR(J19/H19,"0") -> 0.95454545 | AJ19: =IFERROR(F19/E19,"0") -> 0.98550725 | AK19: =IFERROR(F19/(F19+G19),"0") -> 1 | AL19: =IFERROR(AK19*AJ19*AI19,"0") -> 0.94071146
A20: =A19+1 -> 46037 | B20: =A20 -> 46037 | C20: Morning | D20: Winding Machine | E20: 1410 | F20: 1395 | G20: 0 | H20: 660 | I20: =IF(E20<>"",30,0) -> 30 | J20: =H20-AH20 -> 630 | Z20: =IF(E20<>"",30,0) -> 30 | AH20: =SUM(K20:AG20) -> 30 | AI20: =IFERROR(J20/H20,"0") -> 0.95454545 | AJ20: =IFERROR(F20/E20,"0") -> 0.9893617 | AK20: =IFERROR(F20/(F20+G20),"0") -> 1 | AL20: =IFERROR(AK20*AJ20*AI20,"0") -> 0.94439072
A21: =A20+1 -> 46038 | B21: =A21 -> 46038 | C21: Morning | D21: Winding Machine | E21: 1390 | F21: 1375 | G21: 0 | H21: 480 | I21: =IF(E21<>"",30,0) -> 30 | J21: =H21-AH21 -> 450 | Z21: =IF(E21<>"",30,0) -> 30 | AH21: =SUM(K21:AG21) -> 30 | AI21: =IFERROR(J21/H21,"0") -> 0.9375 | AJ21: =IFERROR(F21/E21,"0") -> 0.98920863 | AK21: =IFERROR(F21/(F21+G21),"0") -> 1 | AL21: =IFERROR(AK21*AJ21*AI21,"0") -> 0.92738309
A22: =A21+1 -> 46039 | B22: =A22 -> 46039 | C22: Morning | D22: Winding Machine | E22: 1040 | F22: 1025 | G22: 0 | H22: 660 | I22: =IF(E22<>"",30,0) -> 30 | J22: =H22-AH22 -> 630 | Z22: =IF(E22<>"",30,0) -> 30 | AH22: =SUM(K22:AG22) -> 30 | AI22: =IFERROR(J22/H22,"0") -> 0.95454545 | AJ22: =IFERROR(F22/E22,"0") -> 0.98557692 | AK22: =IFERROR(F22/(F22+G22),"0") -> 1 | AL22: =IFERROR(AK22*AJ22*AI22,"0") -> 0.94077797
A23: =A22+1 -> 46040 | B23: =A23 -> 46040 | C23: Morning | D23: Winding Machine | E23: 1415 | F23: 1400 | G23: 0 | H23: 660 | I23: =IF(E23<>"",30,0) -> 30 | J23: =H23-AH23 -> 630 | Z23: =IF(E23<>"",30,0) -> 30 | AH23: =SUM(K23:AG23) -> 30 | AI23: =IFERROR(J23/H23,"0") -> 0.95454545 | AJ23: =IFERROR(F23/E23,"0") -> 0.98939929 | AK23: =IFERROR(F23/(F23+G23),"0") -> 1 | AL23: =IFERROR(AK23*AJ23*AI23,"0") -> 0.9444266
A24: =A23+1 -> 46041 | B24: =A24 -> 46041 | C24: Morning | D24: Winding Machine | E24: 1415 | F24: 1400 | G24: 0 | H24: 660 | I24: =IF(E24<>"",30,0) -> 30 | J24: =H24-AH24 -> 630 | Z24: =IF(E24<>"",30,0) -> 30 | AH24: =SUM(K24:AG24) -> 30 | AI24: =IFERROR(J24/H24,"0") -> 0.95454545 | AJ24: =IFERROR(F24/E24,"0") -> 0.98939929 | AK24: =IFERROR(F24/(F24+G24),"0") -> 1 | AL24: =IFERROR(AK24*AJ24*AI24,"0") -> 0.9444266
A25: =A24+1 -> 46042 | B25: =A25 -> 46042 | C25: Morning | D25: Winding Machine | E25: 1410 | F25: 1395 | G25: 0 | H25: 660 | I25: =IF(E25<>"",30,0) -> 30 | J25: =H25-AH25 -> 630 | Z25: =IF(E25<>"",30,0) -> 30 | AH25: =SUM(K25:AG25) -> 30 | AI25: =IFERROR(J25/H25,"0") -> 0.95454545 | AJ25: =IFERROR(F25/E25,"0") -> 0.9893617 | AK25: =IFERROR(F25/(F25+G25),"0") -> 1 | AL25: =IFERROR(AK25*AJ25*AI25,"0") -> 0.94439072
A26: =A25+1 -> 46043 | B26: =A26 -> 46043 | C26: Morning | D26: Winding Machine | E26: 1410 | F26: 1395 | G26: 0 | H26: 660 | I26: =IF(E26<>"",30,0) -> 30 | J26: =H26-AH26 -> 630 | Z26: =IF(E26<>"",30,0) -> 30 | AH26: =SUM(K26:AG26) -> 30 | AI26: =IFERROR(J26/H26,"0") -> 0.95454545 | AJ26: =IFERROR(F26/E26,"0") -> 0.9893617 | AK26: =IFERROR(F26/(F26+G26),"0") -> 1 | AL26: =IFERROR(AK26*AJ26*AI26,"0") -> 0.94439072
A27: =A26+1 -> 46044 | B27: =A27 -> 46044 | C27: Morning | D27: Winding Machine | E27: 790 | F27: 775 | G27: 0 | H27: 660 | I27: =IF(E27<>"",30,0) -> 30 | J27: =H27-AH27 -> 630 | Z27: =IF(E27<>"",30,0) -> 30 | AH27: =SUM(K27:AG27) -> 30 | AI27: =IFERROR(J27/H27,"0") -> 0.95454545 | AJ27: =IFERROR(F27/E27,"0") -> 0.98101266 | AK27: =IFERROR(F27/(F27+G27),"0") -> 1 | AL27: =IFERROR(AK27*AJ27*AI27,"0") -> 0.93642117
A28: =A27+1 -> 46045 | B28: =A28 -> 46045 | C28: Morning | D28: Winding Machine | F28: 0 | G28: 0 | I28: =IF(E28<>"",30,0) -> 0 | J28: =H28-AH28 -> 0 | Z28: =IF(E28<>"",30,0) -> 0 | AH28: =SUM(K28:AG28) -> 0 | AI28: =IFERROR(J28/H28,"0") -> 0 | AJ28: =IFERROR(F28/E28,"0") -> 0 | AK28: =IFERROR(F28/(F28+G28),"0") -> 0 | AL28: =IFERROR(AK28*AJ28*AI28,"0") -> 0
A29: =A28+1 -> 46046 | B29: =A29 -> 46046 | C29: Morning | D29: Winding Machine | E29: 1405 | F29: 1390 | G29: 0 | H29: 660 | I29: =IF(E29<>"",30,0) -> 30 | J29: =H29-AH29 -> 630 | Z29: =IF(E29<>"",30,0) -> 30 | AH29: =SUM(K29:AG29) -> 30 | AI29: =IFERROR(J29/H29,"0") -> 0.95454545 | AJ29: =IFERROR(F29/E29,"0") -> 0.98932384 | AK29: =IFERROR(F29/(F29+G29),"0") -> 1 | AL29: =IFERROR(AK29*AJ29*AI29,"0") -> 0.94435458
A30: =A29+1 -> 46047 | B30: =A30 -> 46047 | C30: Morning | D30: Winding Machine | E30: 1335 | F30: 1320 | G30: 0 | H30: 660 | I30: =IF(E30<>"",30,0) -> 30 | J30: =H30-AH30 -> 630 | Z30: =IF(E30<>"",30,0) -> 30 | AH30: =SUM(K30:AG30) -> 30 | AI30: =IFERROR(J30/H30,"0") -> 0.95454545 | AJ30: =IFERROR(F30/E30,"0") -> 0.98876404 | AK30: =IFERROR(F30/(F30+G30),"0") -> 1 | AL30: =IFERROR(AK30*AJ30*AI30,"0") -> 0.94382022
A31: =A30+1 -> 46048 | B31: =A31 -> 46048 | C31: Morning | D31: Winding Machine | E31: 1415 | F31: 1400 | G31: 0 | H31: 480 | I31: =IF(E31<>"",30,0) -> 30 | J31: =H31-AH31 -> 450 | Z31: =IF(E31<>"",30,0) -> 30 | AH31: =SUM(K31:AG31) -> 30 | AI31: =IFERROR(J31/H31,"0") -> 0.9375 | AJ31: =IFERROR(F31/E31,"0") -> 0.98939929 | AK31: =IFERROR(F31/(F31+G31),"0") -> 1 | AL31: =IFERROR(AK31*AJ31*AI31,"0") -> 0.92756184
A32: =A31+1 -> 46049 | B32: =A32 -> 46049 | C32: Morning | D32: Winding Machine | E32: 1040 | F32: 1025 | G32: 0 | H32: 480 | I32: =IF(E32<>"",30,0) -> 30 | J32: =H32-AH32 -> 450 | Z32: =IF(E32<>"",30,0) -> 30 | AH32: =SUM(K32:AG32) -> 30 | AI32: =IFERROR(J32/H32,"0") -> 0.9375 | AJ32: =IFERROR(F32/E32,"0") -> 0.98557692 | AK32: =IFERROR(F32/(F32+G32),"0") -> 1 | AL32: =IFERROR(AK32*AJ32*AI32,"0") -> 0.92397837
A33: =A32+1 -> 46050 | B33: =A33 -> 46050 | C33: Morning | D33: Winding Machine | E33: 685 | F33: 670 | G33: 0 | H33: 480 | I33: =IF(E33<>"",30,0) -> 30 | J33: =H33-AH33 -> 450 | Z33: =IF(E33<>"",30,0) -> 30 | AH33: =SUM(K33:AG33) -> 30 | AI33: =IFERROR(J33/H33,"0") -> 0.9375 | AJ33: =IFERROR(F33/E33,"0") -> 0.97810219 | AK33: =IFERROR(F33/(F33+G33),"0") -> 1 | AL33: =IFERROR(AK33*AJ33*AI33,"0") -> 0.9169708
A34: =A33+1 -> 46051 | B34: =A34 -> 46051 | C34: Morning | D34: Winding Machine | E34: 975 | F34: 960 | G34: 0 | H34: 480 | I34: =IF(E34<>"",30,0) -> 30 | J34: =H34-AH34 -> 450 | Z34: =IF(E34<>"",30,0) -> 30 | AH34: =SUM(K34:AG34) -> 30 | AI34: =IFERROR(J34/H34,"0") -> 0.9375 | AJ34: =IFERROR(F34/E34,"0") -> 0.98461538 | AK34: =IFERROR(F34/(F34+G34),"0") -> 1 | AL34: =IFERROR(AK34*AJ34*AI34,"0") -> 0.92307692
A35: =A34+1 -> 46052 | B35: =A35 -> 46052 | C35: Morning | D35: Winding Machine | E35: 1020 | F35: 1005 | G35: 0 | H35: 480 | I35: =IF(E35<>"",30,0) -> 30 | J35: =H35-AH35 -> 450 | Z35: =IF(E35<>"",30,0) -> 30 | AH35: =SUM(K35:AG35) -> 30 | AI35: =IFERROR(J35/H35,"0") -> 0.9375 | AJ35: =IFERROR(F35/E35,"0") -> 0.98529412 | AK35: =IFERROR(F35/(F35+G35),"0") -> 1 | AL35: =IFERROR(AK35*AJ35*AI35,"0") -> 0.92371324
A36: =A35+1 -> 46053 | B36: =A36 -> 46053 | C36: Morning | D36: Winding Machine | E36: 1025 | F36: 1010 | G36: 0 | H36: 480 | I36: =IF(E36<>"",30,0) -> 30 | J36: =H36-AH36 -> 450 | Z36: =IF(E36<>"",30,0) -> 30 | AH36: =SUM(K36:AG36) -> 30 | AI36: =IFERROR(J36/H36,"0") -> 0.9375 | AJ36: =IFERROR(F36/E36,"0") -> 0.98536585 | AK36: =IFERROR(F36/(F36+G36),"0") -> 1 | AL36: =IFERROR(AK36*AJ36*AI36,"0") -> 0.92378049
A37: Total: | E37: 36297 | F37: =SUM(F6:F36) -> 35862 | G37: =SUM(G6:G36) -> 0 | H37: =SUM(H6:H36) -> 17700 | I37: =SUM(I6:I36) -> 870 | J37: =SUM(J6:J36) -> 16830 | K37: =SUM(K6:K36) -> 0 | L37: =SUM(L6:L36) -> 0 | M37: =SUM(M6:M36) -> 0 | ... AH37: =SUM(AH6:AH36) -> 870 | AI37: =IFERROR(J37/H37,0) -> 0.95084746 | AJ37: =IFERROR(F37/E37,0) -> 0.98801554 | AK37: =IFERROR(F37/(F37+G37),0) -> 1 | AL37: =IFERROR(AK37*AJ37*AI37,0) -> 0.93945206

Sheet Fan Power Press & Stamping
A1: MEP FAN LTD.
A2: Production Performance Analysis Report | AR2: 46023 | AS2: 45689 | AT2: 45717 | AU2: 45748 | AV2: 45778 | AW2: 45809 | AX2: 45839 | AY2: 45870 | AZ2: 45901 | BA2: 45931 | BB2: 45962 | BC2: 45992
A3: ='Fan Lathe'!AM3 -> 46023 | P3: ="Fan Power Press Section ("&TEXT('Fan Lathe'!AM3,"mmmm yyyy")&")" -> Fan Power Press Section (January 2026)
K4: 10 | L4: 11 | M4: 12 | N4: 13 | O4: 14 | P4: 15 | Q4: 16 | R4: 17 | S4: 18 | T4: 19 | U4: 20 | V4: 21 | W4: 22 | X4: 23 | Y4: 33 | Z4: 34 | AA4: 35 | AB4: 24 | AC4: 25 | AD4: 26 | AE4: 27 | AF4: 28 | AG4: 29 | AH4: 30 | AI4: 31 | AJ4: 32
A5: Date | B5: Day | C5: Shift | D5: Machine Name | E5: Production Capacity (Pcs) | F5: Actual Prd. (Pcs) | G5: Rejection (Pcs) | H5: Planned Prd. Time (Min) | I5: Expected DownTime (Min) | J5: Total Prd. Run Time (Min) | K5: Heater/Coil Problem | L5: Power Shutdown | M5: Machine Breakdown | N5: Die/ Mold Problem | O5: Model/ Die Change | P5: Air Presser Problem | Q5: Water line Problem | R5: Lift Problem | S5: D Coil Insert | T5: RM Shortage | U5: Crean Problem | V5: Worker Absent | W5: Printer M/C Problem | X5: UPS shutdown | Y5: Box Moving | Z5: Up Casting Meeting | AA5: Sheet Cutting& Pipe Carry | AB5: Load Problem | AC5: Namaz | AD5: Conveyor Belt Problem | AE5: Fitting Problem | AF5: Gas Presser Problem | AG5: Mold polish & Clean | AH5: Alu. Ash Extraction | AI5: Robot Problems | AJ5: Alu. Recipe Problem | AK5: Total Down Time (Mins) | AL5: Availability (%) | AM5: Performance (%) | AN5: Quality (%) | AO5: OEE (%) | AP5: Remarks
A6: =A3 -> 46023 | B6: =A6 -> 46023 | C6: Morning | D6: Shank | E6: 3500 | H6: 660 | I6: =IF(E6<>"",120,0) -> 120 | J6: =H6-AK6 -> 0 | M6: 660 | AK6: =SUM(K6:AJ6) -> 660 | AL6: =IFERROR(J6/H6,"0") -> 0 | AM6: =IFERROR(F6/E6,"0") -> 0 | AN6: =IFERROR(F6/(F6+G6),"0") -> 0 | AO6: =IFERROR(AN6*AM6*AL6,"0") -> 0 | AQ6: 46023
C7: Morning | D7: Clamp | E7: 3000 | H7: 660 | I7: =IF(E7<>"",120,0) -> 120 | J7: =H7-AK7 -> 0 | M7: 660 | AK7: =SUM(K7:AJ7) -> 660 | AL7: =IFERROR(J7/H7,"0") -> 0 | AM7: =IFERROR(F7/E7,"0") -> 0 | AN7: =IFERROR(F7/(F7+G7),"0") -> 0 | AO7: =IFERROR(AN7*AM7*AL7,"0") -> 0 | AQ7: 46054
C8: Morning | D8: Rotor & Stator | E8: 2500 | F8: 2072 | G8: 12 | H8: 660 | I8: =IF(E8<>"",120,0) -> 120 | J8: =H8-AK8 -> 520 | S8: 60 | Y8: 50 | AC8: 30 | AK8: =SUM(K8:AJ8) -> 140 | AL8: =IFERROR(J8/H8,"0") -> 0.78787879 | AM8: =IFERROR(F8/E8,"0") -> 0.8288 | AN8: =IFERROR(F8/(F8+G8),"0") -> 0.99424184 | AO8: =IFERROR(AN8*AM8*AL8,"0") -> 0.6492339 | AQ8: 46082
C9: Morning | D9: Blade(5601) | E9: 2100 | H9: 660 | I9: =IF(E9<>"",120,0) -> 120 | J9: =H9-AK9 -> 0 | T9: 660 | AK9: =SUM(K9:AJ9) -> 660 | AL9: =IFERROR(J9/H9,"0") -> 0 | AM9: =IFERROR(F9/E9,"0") -> 0 | AN9: =IFERROR(F9/(F9+G9),"0") -> 0 | AO9: =IFERROR(AN9*AM9*AL9,"0") -> 0 | AQ9: 46113
C10: Morning | D10: Downpipe | E10: 1550 | F10: 1500 | H10: 660 | I10: =IF(E10<>"",120,0) -> 120 | J10: =H10-AK10 -> 639 | AC10: 21 | AK10: =SUM(K10:AJ10) -> 21 | AL10: =IFERROR(J10/H10,"0") -> 0.96818182 | AM10: =IFERROR(F10/E10,"0") -> 0.96774194 | AN10: =IFERROR(F10/(F10+G10),"0") -> 1 | AO10: =IFERROR(AN10*AM10*AL10,"0") -> 0.93695015 | AQ10: 46143
A11: =A6+1 -> 46024 | B11: =A11 -> 46024 | C11: Morning | D11: Shank | E11: 2550 | H11: 480 | I11: =IF(E11<>"",120,0) -> 120 | J11: =H11-AK11 -> 0 | M11: 480 | AK11: =SUM(K11:AJ11) -> 480 | AL11: =IFERROR(J11/H11,"0") -> 0 | AM11: =IFERROR(F11/E11,"0") -> 0 | AN11: =IFERROR(F11/(F11+G11),"0") -> 0 | AO11: =IFERROR(AN11*AM11*AL11,"0") -> 0 | AQ11: 46174
C12: Morning | D12: Clamp | E12: 2200 | H12: 480 | I12: =IF(E12<>"",120,0) -> 120 | J12: =H12-AK12 -> 0 | M12: 480 | AK12: =SUM(K12:AJ12) -> 480 | AL12: =IFERROR(J12/H12,"0") -> 0 | AM12: =IFERROR(F12/E12,"0") -> 0 | AN12: =IFERROR(F12/(F12+G12),"0") -> 0 | AO12: =IFERROR(AN12*AM12*AL12,"0") -> 0 | AQ12: 46204
C13: Morning | D13: Rotor & Stator | E13: 1820 | F13: 1230 | G13: 6 | H13: 480 | I13: =IF(E13<>"",120,0) -> 120 | J13: =H13-AK13 -> 325 | S13: 50 | Y13: 40 | AC13: 45 | AG13: 20 | AK13: =SUM(K13:AJ13) -> 155 | AL13: =IFERROR(J13/H13,"0") -> 0.67708333 | AM13: =IFERROR(F13/E13,"0") -> 0.67582418 | AN13: =IFERROR(F13/(F13+G13),"0") -> 0.99514563 | AO13: =IFERROR(AN13*AM13*AL13,"0") -> 0.45536798 | AQ13: 46235
C14: Morning | D14: Blade(5601) | E14: 1500 | H14: 480 | I14: =IF(E14<>"",120,0) -> 120 | J14: =H14-AK14 -> 0 | T14: 480 | AK14: =SUM(K14:AJ14) -> 480 | AL14: =IFERROR(J14/H14,"0") -> 0 | AM14: =IFERROR(F14/E14,"0") -> 0 | AN14: =IFERROR(F14/(F14+G14),"0") -> 0 | AO14: =IFERROR(AN14*AM14*AL14,"0") -> 0 | AQ14: 46266
C15: Morning | D15: Downpipe | E15: 1130 | F15: 1000 | G15: 2 | H15: 480 | I15: =IF(E15<>"",120,0) -> 120 | J15: =H15-AK15 -> 425 | AA15: 30 | AC15: 25 | AK15: =SUM(K15:AJ15) -> 55 | AL15: =IFERROR(J15/H15,"0") -> 0.88541667 | AM15: =IFERROR(F15/E15,"0") -> 0.88495575 | AN15: =IFERROR(F15/(F15+G15),"0") -> 0.99800399 | AO15: =IFERROR(AN15*AM15*AL15,"0") -> 0.78199059 | AQ15: 46296
A16: =A11+1 -> 46025 | B16: =A16 -> 46025 | C16: Morning | D16: Shank | E16: 3500 | H16: 660 | I16: =IF(E16<>"",120,0) -> 120 | J16: =H16-AK16 -> 0 | M16: 660 | AK16: =SUM(K16:AJ16) -> 660 | AL16: =IFERROR(J16/H16,"0") -> 0 | AM16: =IFERROR(F16/E16,"0") -> 0 | AN16: =IFERROR(F16/(F16+G16),"0") -> 0 | AO16: =IFERROR(AN16*AM16*AL16,"0") -> 0 | AQ16: 46327
C17: Morning | D17: Clamp | E17: 3000 | F17: 2125 | G17: 4 | H17: 660 | I17: =IF(E17<>"",120,0) -> 120 | J17: =H17-AK17 -> 470 | M17: 70 | N17: 60 | Y17: 30 | AC17: 30 | AK17: =SUM(K17:AJ17) -> 190 | AL17: =IFERROR(J17/H17,"0") -> 0.71212121 | AM17: =IFERROR(F17/E17,"0") -> 0.70833333 | AN17: =IFERROR(F17/(F17+G17),"0") -> 0.99812118 | AO17: =IFERROR(AN17*AM17*AL17,"0") -> 0.50347148 | AQ17: 46357
C18: Morning | D18: Rotor & Stator | E18: 2500 | F18: 1767 | G18: 6 | H18: 660 | I18: =IF(E18<>"",120,0) -> 120 | J18: =H18-AK18 -> 470 | S18: 70 | Y18: 60 | AC18: 30 | AG18: 30 | AK18: =SUM(K18:AJ18) -> 190 | AL18: =IFERROR(J18/H18,"0") -> 0.71212121 | AM18: =IFERROR(F18/E18,"0") -> 0.7068 | AN18: =IFERROR(F18/(F18+G18),"0") -> 0.99661591 | AO18: =IFERROR(AN18*AM18*AL18,"0") -> 0.50162397
C19: Morning | D19: Blade(5601) | E19: 2100 | F19: 600 | G19: 2 | H19: 660 | I19: =IF(E19<>"",120,0) -> 120 | J19: =H19-AK19 -> 190 | AA19: 445 | AC19: 25 | AK19: =SUM(K19:AJ19) -> 470 | AL19: =IFERROR(J19/H19,"0") -> 0.28787879 | AM19: =IFERROR(F19/E19,"0") -> 0.28571429 | AN19: =IFERROR(F19/(F19+G19),"0") -> 0.99667774 | AO19: =IFERROR(AN19*AM19*AL19,"0") -> 0.081977823
C20: Morning | D20: Downpipe | E20: 1550 | F20: 650 | H20: 660 | I20: =IF(E20<>"",120,0) -> 120 | J20: =H20-AK20 -> 280 | M20: 300 | AA20: 60 | AC20: 20 | AK20: =SUM(K20:AJ20) -> 380 | AL20: =IFERROR(J20/H20,"0") -> 0.42424242 | AM20: =IFERROR(F20/E20,"0") -> 0.41935484 | AN20: =IFERROR(F20/(F20+G20),"0") -> 1 | AO20: =IFERROR(AN20*AM20*AL20,"0") -> 0.17790811
A21: =A16+1 -> 46026 | B21: =A21 -> 46026 | C21: Morning | D21: Shank | E21: 3500 | F21: 3253 | G21: 8 | H21: 660 | I21: =IF(E21<>"",120,0) -> 120 | J21: =H21-AK21 -> 610 | Y21: 25 | AC21: 25 | AK21: =SUM(K21:AJ21) -> 50 | AL21: =IFERROR(J21/H21,"0") -> 0.92424242 | AM21: =IFERROR(F21/E21,"0") -> 0.92942857 | AN21: =IFERROR(F21/(F21+G21),"0") -> 0.99754676 | AO21: =IFERROR(AN21*AM21*AL21,"0") -> 0.85690994
C22: Morning | D22: Clamp | E22: 3000 | H22: 660 | I22: =IF(E22<>"",120,0) -> 120 | J22: =H22-AK22 -> 0 | M22: 660 | AK22: =SUM(K22:AJ22) -> 660 | AL22: =IFERROR(J22/H22,"0") -> 0 | AM22: =IFERROR(F22/E22,"0") -> 0 | AN22: =IFERROR(F22/(F22+G22),"0") -> 0 | AO22: =IFERROR(AN22*AM22*AL22,"0") -> 0
C23: Morning | D23: Rotor & Stator | E23: 2500 | F23: 1139 | H23: 660 | I23: =IF(E23<>"",120,0) -> 120 | J23: =H23-AK23 -> 310 | S23: 40 | T23: 250 | Y23: 35 | AC23: 25 | AK23: =SUM(K23:AJ23) -> 350 | AL23: =IFERROR(J23/H23,"0") -> 0.46969697 | AM23: =IFERROR(F23/E23,"0") -> 0.4556 | AN23: =IFERROR(F23/(F23+G23),"0") -> 1 | AO23: =IFERROR(AN23*AM23*AL23,"0") -> 0.21399394
C24: Morning | D24: Blade(5601) | E24: 2100 | F24: 2000 | G24: 2 | H24: 660 | I24: =IF(E24<>"",120,0) -> 120 | J24: =H24-AK24 -> 630 | AC24: 30 | AK24: =SUM(K24:AJ24) -> 30 | AL24: =IFERROR(J24/H24,"0") -> 0.95454545 | AM24: =IFERROR(F24/E24,"0") -> 0.95238095 | AN24: =IFERROR(F24/(F24+G24),"0") -> 0.999001 | AO24: =IFERROR(AN24*AM24*AL24,"0") -> 0.90818273
C25: Morning | D25: Downpipe | E25: 1550 | F25: 1500 | H25: 660 | I25: =IF(E25<>"",120,0) -> 120 | J25: =H25-AK25 -> 635 | AA25: 25 | AK25: =SUM(K25:AJ25) -> 25 | AL25: =IFERROR(J25/H25,"0") -> 0.96212121 | AM25: =IFERROR(F25/E25,"0") -> 0.96774194 | AN25: =IFERROR(F25/(F25+G25),"0") -> 1 | AO25: =IFERROR(AN25*AM25*AL25,"0") -> 0.93108504
A26: =A21+1 -> 46027 | B26: =A26 -> 46027 | C26: Morning | D26: Shank | E26: 3500 | F26: 3353 | G26: 6 | H26: 660 | I26: =IF(E26<>"",120,0) -> 120 | J26: =H26-AK26 -> 660 | AK26: =SUM(K26:AJ26) -> 0 | AL26: =IFERROR(J26/H26,"0") -> 1 | AM26: =IFERROR(F26/E26,"0") -> 0.958 | AN26: =IFERROR(F26/(F26+G26),"0") -> 0.99821375 | AO26: =IFERROR(AN26*AM26*AL26,"0") -> 0.95628878
C27: Morning | D27: Clamp | E27: 3000 | H27: 660 | I27: =IF(E27<>"",120,0) -> 120 | J27: =H27-AK27 -> 0 | M27: 660 | AK27: =SUM(K27:AJ27) -> 660 | AL27: =IFERROR(J27/H27,"0") -> 0 | AM27: =IFERROR(F27/E27,"0") -> 0 | AN27: =IFERROR(F27/(F27+G27),"0") -> 0 | AO27: =IFERROR(AN27*AM27*AL27,"0") -> 0
C28: Morning | D28: Rotor & Stator | E28: 2500 | H28: 660 | I28: =IF(E28<>"",120,0) -> 120 | J28: =H28-AK28 -> 0 | T28: 660 | AK28: =SUM(K28:AJ28) -> 660 | AL28: =IFERROR(J28/H28,"0") -> 0 | AM28: =IFERROR(F28/E28,"0") -> 0 | AN28: =IFERROR(F28/(F28+G28),"0") -> 0 | AO28: =IFERROR(AN28*AM28*AL28,"0") -> 0
C29: Morning | D29: Blade(5601) | E29: 2100 | F29: 2000 | H29: 660 | I29: =IF(E29<>"",120,0) -> 120 | J29: =H29-AK29 -> 630 | AC29: 30 | AK29: =SUM(K29:AJ29) -> 30 | AL29: =IFERROR(J29/H29,"0") -> 0.95454545 | AM29: =IFERROR(F29/E29,"0") -> 0.95238095 | AN29: =IFERROR(F29/(F29+G29),"0") -> 1 | AO29: =IFERROR(AN29*AM29*AL29,"0") -> 0.90909091
C30: Morning | D30: Downpipe | E30: 1550 | F30: 1500 | G30: 2 | H30: 660 | I30: =IF(E30<>"",120,0) -> 120 | J30: =H30-AK30 -> 635 | AA30: 25 | AK30: =SUM(K30:AJ30) -> 25 | AL30: =IFERROR(J30/H30,"0") -> 0.96212121 | AM30: =IFERROR(F30/E30,"0") -> 0.96774194 | AN30: =IFERROR(F30/(F30+G30),"0") -> 0.99866844 | AO30: =IFERROR(AN30*AM30*AL30,"0") -> 0.92984525
A31: =A26+1 -> 46028 | B31: =A31 -> 46028 | C31: Morning | D31: Shank | E31: 3500 | F31: 3333 | H31: 660 | I31: =IF(E31<>"",120,0) -> 120 | J31: =H31-AK31 -> 630 | AC31: 30 | AK31: =SUM(K31:AJ31) -> 30 | AL31: =IFERROR(J31/H31,"0") -> 0.95454545 | AM31: =IFERROR(F31/E31,"0") -> 0.95228571 | AN31: =IFERROR(F31/(F31+G31),"0") -> 1 | AO31: =IFERROR(AN31*AM31*AL31,"0") -> 0.909
C32: Morning | D32: Clamp | E32: 3000 | F32: 2550 | H32: 660 | I32: =IF(E32<>"",120,0) -> 120 | J32: =H32-AK32 -> 630 | AC32: 30 | AK32: =SUM(K32:AJ32) -> 30 | AL32: =IFERROR(J32/H32,"0") -> 0.95454545 | AM32: =IFERROR(F32/E32,"0") -> 0.85 | AN32: =IFERROR(F32/(F32+G32),"0") -> 1 | AO32: =IFERROR(AN32*AM32*AL32,"0") -> 0.81136364
C33: Morning | D33: Rotor & Stator | E33: 2500 | H33: 660 | I33: =IF(E33<>"",120,0) -> 120 | J33: =H33-AK33 -> 0 | N33: 660 | AK33: =SUM(K33:AJ33) -> 660 | AL33: =IFERROR(J33/H33,"0") -> 0 | AM33: =IFERROR(F33/E33,"0") -> 0 | AN33: =IFERROR(F33/(F33+G33),"0") -> 0 | AO33: =IFERROR(AN33*AM33*AL33,"0") -> 0
C34: Morning | D34: Blade(5601) | E34: 2100 | F34: 2000 | H34: 660 | I34: =IF(E34<>"",120,0) -> 120 | J34: =H34-AK34 -> 630 | AC34: 30 | AK34: =SUM(K34:AJ34) -> 30 | AL34: =IFERROR(J34/H34,"0") -> 0.95454545 | AM34: =IFERROR(F34/E34,"0") -> 0.95238095 | AN34: =IFERROR(F34/(F34+G34),"0") -> 1 | AO34: =IFERROR(AN34*AM34*AL34,"0") -> 0.90909091
C35: Morning | D35: Downpipe | E35: 1550 | F35: 1500 | H35: 660 | I35: =IF(E35<>"",120,0) -> 120 | J35: =H35-AK35 -> 635 | AA35: 25 | AK35: =SUM(K35:AJ35) -> 25 | AL35: =IFERROR(J35/H35,"0") -> 0.96212121 | AM35: =IFERROR(F35/E35,"0") -> 0.96774194 | AN35: =IFERROR(F35/(F35+G35),"0") -> 1 | AO35: =IFERROR(AN35*AM35*AL35,"0") -> 0.93108504
A36: =A31+1 -> 46029 | B36: =A36 -> 46029 | C36: Morning | D36: Shank | E36: 3500 | F36: 3333 | G36: 6 | H36: 660 | I36: =IF(E36<>"",120,0) -> 120 | J36: =H36-AK36 -> 630 | AC36: 30 | AK36: =SUM(K36:AJ36) -> 30 | AL36: =IFERROR(J36/H36,"0") -> 0.95454545 | AM36: =IFERROR(F36/E36,"0") -> 0.95228571 | AN36: =IFERROR(F36/(F36+G36),"0") -> 0.99820305 | AO36: =IFERROR(AN36*AM36*AL36,"0") -> 0.90736658
C37: Morning | D37: Clamp | E37: 3000 | H37: 660 | I37: =IF(E37<>"",120,0) -> 120 | J37: =H37-AK37 -> 0 | M37: 660 | AK37: =SUM(K37:AJ37) -> 660 | AL37: =IFERROR(J37/H37,"0") -> 0 | AM37: =IFERROR(F37/E37,"0") -> 0 | AN37: =IFERROR(F37/(F37+G37),"0") -> 0 | AO37: =IFERROR(AN37*AM37*AL37,"0") -> 0
C38: Morning | D38: Rotor & Stator | E38: 2500 | H38: 660 | I38: =IF(E38<>"",120,0) -> 120 | J38: =H38-AK38 -> 0 | N38: 660 | AK38: =SUM(K38:AJ38) -> 660 | AL38: =IFERROR(J38/H38,"0") -> 0 | AM38: =IFERROR(F38/E38,"0") -> 0 | AN38: =IFERROR(F38/(F38+G38),"0") -> 0 | AO38: =IFERROR(AN38*AM38*AL38,"0") -> 0
C39: Morning | D39: Blade(5601) | E39: 2100 | F39: 2000 | H39: 660 | I39: =IF(E39<>"",120,0) -> 120 | J39: =H39-AK39 -> 630 | AC39: 30 | AK39: =SUM(K39:AJ39) -> 30 | AL39: =IFERROR(J39/H39,"0") -> 0.95454545 | AM39: =IFERROR(F39/E39,"0") -> 0.95238095 | AN39: =IFERROR(F39/(F39+G39),"0") -> 1 | AO39: =IFERROR(AN39*AM39*AL39,"0") -> 0.90909091
C40: Morning | D40: Downpipe | E40: 1550 | F40: 1500 | G40: 4 | H40: 660 | I40: =IF(E40<>"",120,0) -> 120 | J40: =H40-AK40 -> 635 | AA40: 25 | AK40: =SUM(K40:AJ40) -> 25 | AL40: =IFERROR(J40/H40,"0") -> 0.96212121 | AM40: =IFERROR(F40/E40,"0") -> 0.96774194 | AN40: =IFERROR(F40/(F40+G40),"0") -> 0.99734043 | AO40: =IFERROR(AN40*AM40*AL40,"0") -> 0.92860875
...

Sheet Fan Auto Die Casting
A1: MEP FAN LTD.
A2: Production Performance Analysis Report
A3: ="Fan Auto Die Casting ("&TEXT('Fan Lathe'!AM3,"mmmm yyyy")&")" -> Fan Auto Die Casting (January 2026) | AM3: ='Fan Lathe'!AM3 -> 46023 | AN3: 45658 | AO3: 45689 | AP3: 45717 | AQ3: 45748 | AR3: 45778 | AS3: 45809 | AT3: 45839 | AU3: 45870 | AV3: 45901 | AW3: 45931 | AX3: 45962 | AY3: 45992
K4: 10 | L4: 11 | M4: 12 | N4: 13 | O4: 14 | P4: 15 | Q4: 16 | R4: 17 | S4: 18 | T4: 19 | U4: 20 | V4: 21 | W4: 22 | X4: 23 | Y4: 24 | Z4: 25 | AA4: 26 | AB4: 27 | AC4: 28 | AD4: 29 | AE4: 30 | AF4: 31 | AG4: 32
A5: Date | B5: Day | C5: Shift | D5: Machine Name | E5: Machine Capacity (Pcs) | F5: Actual Prd. (Pcs) | G5: Rejection (Pcs) | H5: Planned Prd. Time (Min) | I5: Expected DownTime (Min) | J5: Total Prd. Run Time (Min) | K5: Heater/Coil Problem | L5: Power Shutdown | M5: Machine Breakdown | N5: Die/ Mold Problem | O5: Model/ Die Change | P5: Air Presser Problem | Q5: Water line Problem | R5: Lift Problem | S5: D Coil Insert | T5: RM Shortage | U5: Crean Problem | V5: Worker Absent | W5: Printer M/C Problem | X5: UPS shutdown | Y5: Load Problem | Z5: Namaz | AA5: Conveyor Belt Problem | AB5: Fitting Problem | AC5: Gas Presser Problem | AD5: Mold polish & Clean | AE5: Alu. Ash Extraction | AF5: Robot Problems | AG5: Alu. Recipe Problem | AH5: Total Down Time (Mins) | AI5: Availability (%) | AJ5: Performance (%) | AK5: Quality (%) | AL5: OEE (%) | AM5: Remarks
A6: =AM3 -> 46023 | B6: =A6 -> 46023 | C6: Morning | D6: Auto Die Casting (Body) | E6: 3200 | F6: 1283 | G6: 22 | H6: 1440 | I6: =IF(E6<>"",180,0) -> 180 | J6: =H6-AH6 -> 580 | M6: 720 | P6: 10 | AD6: 10 | AG6: 120 | AH6: =SUM(K6:AG6) -> 860 | AI6: =IFERROR(J6/H6,"0") -> 0.40277778 | AJ6: =IFERROR(F6/E6,"0") -> 0.4009375 | AK6: =IFERROR(F6/(F6+G6),"0") -> 0.98314176 | AL6: =IFERROR(AK6*AJ6*AI6,"0") -> 0.1587663
C7: Morning | D7: Auto Die Casting (Cover) | E7: 3200 | F7: 1476 | G7: 12 | H7: 1440 | I7: =IF(E7<>"",180,0) -> 180 | J7: =H7-AH7 -> 580 | M7: 720 | P7: 10 | AD7: 10 | AG7: 120 | AH7: =SUM(K7:AG7) -> 860 | AI7: =IFERROR(J7/H7,"0") -> 0.40277778 | AJ7: =IFERROR(F7/E7,"0") -> 0.46125 | AK7: =IFERROR(F7/(F7+G7),"0") -> 0.99193548 | AL7: =IFERROR(AK7*AJ7*AI7,"0") -> 0.18428301
A8: =A6+1 -> 46024 | B8: =A8 -> 46024 | C8: Morning | D8: Auto Die Casting (Body) | E8: 3200 | F8: 1487 | G8: 23 | H8: 1440 | I8: =IF(E8<>"",180,0) -> 180 | J8: =H8-AH8 -> 670 | M8: 720 | N8: 50 | AH8: =SUM(K8:AG8) -> 770 | AI8: =IFERROR(J8/H8,"0") -> 0.46527778 | AJ8: =IFERROR(F8/E8,"0") -> 0.4646875 | AK8: =IFERROR(F8/(F8+G8),"0") -> 0.98476821 | AL8: =IFERROR(AK8*AJ8*AI8,"0") -> 0.21291552
C9: Morning | D9: Auto Die Casting (Cover) | E9: 3200 | F9: 1552 | G9: 6 | H9: 1440 | I9: =IF(E9<>"",180,0) -> 180 | J9: =H9-AH9 -> 670 | M9: 720 | N9: 50 | AH9: =SUM(K9:AG9) -> 770 | AI9: =IFERROR(J9/H9,"0") -> 0.46527778 | AJ9: =IFERROR(F9/E9,"0") -> 0.485 | AK9: =IFERROR(F9/(F9+G9),"0") -> 0.99614891 | AL9: =IFERROR(AK9*AJ9*AI9,"0") -> 0.22479069
A10: =A8+1 -> 46025 | B10: =A10 -> 46025 | C10: Morning | D10: Auto Die Casting (Body) | E10: 3200 | F10: 1323 | G10: 40 | H10: 1440 | I10: =IF(E10<>"",180,0) -> 180 | J10: =H10-AH10 -> 660 | M10: 720 | Q10: 60 | AH10: =SUM(K10:AG10) -> 780 | AI10: =IFERROR(J10/H10,"0") -> 0.45833333 | AJ10: =IFERROR(F10/E10,"0") -> 0.4134375 | AK10: =IFERROR(F10/(F10+G10),"0") -> 0.97065297 | AL10: =IFERROR(AK10*AJ10*AI10,"0") -> 0.18393115
C11: Morning | D11: Auto Die Casting (Cover) | E11: 3200 | F11: 1550 | G11: 12 | H11: 1440 | I11: =IF(E11<>"",180,0) -> 180 | J11: =H11-AH11 -> 660 | M11: 720 | Q11: 60 | AH11: =SUM(K11:AG11) -> 780 | AI11: =IFERROR(J11/H11,"0") -> 0.45833333 | AJ11: =IFERROR(F11/E11,"0") -> 0.484375 | AK11: =IFERROR(F11/(F11+G11),"0") -> 0.99231754 | AL11: =IFERROR(AK11*AJ11*AI11,"0") -> 0.22029966
A12: =A10+1 -> 46026 | B12: =A12 -> 46026 | C12: Morning | D12: Auto Die Casting (Body) | E12: 3200 | F12: 1349 | G12: 9 | H12: 1440 | I12: =IF(E12<>"",180,0) -> 180 | J12: =H12-AH12 -> 650 | K12: 70 | M12: 720 | AH12: =SUM(K12:AG12) -> 790 | AI12: =IFERROR(J12/H12,"0") -> 0.45138889 | AJ12: =IFERROR(F12/E12,"0") -> 0.4215625 | AK12: =IFERROR(F12/(F12+G12),"0") -> 0.99337261 | AL12: =IFERROR(AK12*AJ12*AI12,"0") -> 0.18902751
C13: Morning | D13: Auto Die Casting (Cover) | E13: 3200 | F13: 1600 | G13: 7 | H13: 1440 | I13: =IF(E13<>"",180,0) -> 180 | J13: =H13-AH13 -> 650 | K13: 70 | M13: 720 | AH13: =SUM(K13:AG13) -> 790 | AI13: =IFERROR(J13/H13,"0") -> 0.45138889 | AJ13: =IFERROR(F13/E13,"0") -> 0.5 | AK13: =IFERROR(F13/(F13+G13),"0") -> 0.99564406 | AL13: =IFERROR(AK13*AJ13*AI13,"0") -> 0.22471133
A14: =A12+1 -> 46027 | B14: =A14 -> 46027 | C14: Morning | D14: Auto Die Casting (Body) | E14: 3200 | F14: 1550 | G14: 5 | H14: 1440 | I14: =IF(E14<>"",180,0) -> 180 | J14: =H14-AH14 -> 695 | L14: 15 | M14: 720 | P14: 10 | AH14: =SUM(K14:AG14) -> 745 | AI14: =IFERROR(J14/H14,"0") -> 0.48263889 | AJ14: =IFERROR(F14/E14,"0") -> 0.484375 | AK14: =IFERROR(F14/(F14+G14),"0") -> 0.99678457 | AL14: =IFERROR(AK14*AJ14*AI14,"0") -> 0.23302651
C15: Morning | D15: Auto Die Casting (Cover) | E15: 3200 | F15: 1550 | G15: 3 | H15: 1440 | I15: =IF(E15<>"",180,0) -> 180 | J15: =H15-AH15 -> 695 | L15: 15 | M15: 720 | P15: 10 | AH15: =SUM(K15:AG15) -> 745 | AI15: =IFERROR(J15/H15,"0") -> 0.48263889 | AJ15: =IFERROR(F15/E15,"0") -> 0.484375 | AK15: =IFERROR(F15/(F15+G15),"0") -> 0.99806825 | AL15: =IFERROR(AK15*AJ15*AI15,"0") -> 0.23332661
